Workbook

Sheet Data Input
B1: Patient ID | C1: Start Time and Date | D1: End Date and Time | E1: Age | F1: Race | G1: Type of Delivery | H1: Date and Time | I1: Pain Medication | J1: Dose | K1: Pain Intensity Rating (Before Medication) | L1: Pain Intensity Rating (After Medication) | M1: Frequency of Pain Medication Used | N1: Question | O1: Comment | P1: Color
A2: =IF(ROW()=2,1,IF(B2=B1,A1,A1+1)) -> 1 | B2: CH001 | C2: 43266.826 | D2: 6/16/2018 1849 | E2: 29 | F2: White | G2: SVD | H2: 6/15/18 2216 | I2: Ibuprofen | J2: 800 | K2: 6 | L2: 5 | M2: 3 | P2: =ISODD(A2) -> TRUE
A3: =IF(ROW()=2,1,IF(B3=B2,A2,A2+1)) -> 1 | B3: CH001 | C3: 43266.826 | D3: 6/16/2018 1849 | E3: 29 | F3: White | G3: SVD | H3: 6/16/18 0510 | I3: Percocet | J3: 1 tab | K3: 8 | L3: 1 | M3: 1 | P3: =ISODD(A3) -> TRUE
A4: =IF(ROW()=2,1,IF(B4=B3,A3,A3+1)) -> 1 | B4: CH001 | C4: 43266.826 | D4: 6/16/2018 1849 | E4: 29 | F4: White | G4: SVD | H4: 6/16/2018 1025 | I4: Ibuprofen | J4: 800 | K4: 6 | L4: 0 | M4: 3 | P4: =ISODD(A4) -> TRUE
A5: =IF(ROW()=2,1,IF(B5=B4,A4,A4+1)) -> 1 | B5: CH001 | C5: 43266.826 | D5: 6/16/2018 1849 | E5: 29 | F5: White | G5: SVD | H5: 6/16/18 1849 | I5: Ibuprofen | J5: 800 | K5: 7 | L5: 3 | M5: 3 | P5: =ISODD(A5) -> TRUE
A6: =IF(ROW()=2,1,IF(B6=B5,A5,A5+1)) -> 2 | B6: KV002 | C6: 06/15/18 0100 | D6: 43267 | E6: 18 | F6: White | G6: SVD | H6: 6/15/18 0538 | I6: Ibuprofen | J6: 800 | K6: 5 | L6: 3 | M6: 3 | P6: =ISODD(A6) -> FALSE
A7: =IF(ROW()=2,1,IF(B7=B6,A6,A6+1)) -> 2 | B7: KV002 | C7: 06/15/18 0100 | D7: 43267 | E7: 18 | F7: White | G7: SVD | H7: 6/15/18 1533 | I7: Ibuprofen | J7: 800 | K7: 5 | L7: 2 | M7: 3 | P7: =ISODD(A7) -> FALSE
A8: =IF(ROW()=2,1,IF(B8=B7,A7,A7+1)) -> 2 | B8: KV002 | C8: 06/15/18 0100 | D8: 43267 | E8: 18 | F8: White | G8: SVD | H8: 6/16/18 0220 | I8: Ibuprofen | J8: 800 | K8: 0 | L8: NA | M8: NA | P8: =ISODD(A8) -> FALSE
A9: =IF(ROW()=2,1,IF(B9=B8,A8,A8+1)) -> 3 | B9: AK003 | C9: 6/15/18 1500 | D9: 6/16/18 0942 | E9: 26 | F9: White | G9: Caesarean | H9: 6/15/18 1550 | I9: Toradol | J9: 30 | K9: 10 | L9: No F/u | M9: 2 | N9: What is "No F/u"? | P9: =ISODD(A9) -> TRUE
A10: =IF(ROW()=2,1,IF(B10=B9,A9,A9+1)) -> 3 | B10: AK003 | C10: 6/15/18 1500 | D10: 6/16/18 0942 | E10: 26 | F10: White | G10: Caesarean | H10: 6/16/18 0835 | I10: Percocet | J10: 1 tab | K10: 6 | L10: 5 | M10: 1 | P10: =ISODD(A10) -> TRUE
A11: =IF(ROW()=2,1,IF(B11=B10,A10,A10+1)) -> 3 | B11: AK003 | C11: 6/15/18 1500 | D11: 6/16/18 0942 | E11: 26 | F11: White | G11: Caesarean | H11: 6/16/18 0942 | I11: Toradol | J11: 30 | K11: 5 | L11: No F/u | M11: 2 | P11: =ISODD(A11) -> TRUE
A12: =IF(ROW()=2,1,IF(B12=B11,A11,A11+1)) -> 4 | B12: JC004 | C12: 6/16/18 0835 | D12: 6/17/18 0702 | E12: 40 | F12: Black | G12: SVD | H12: 6/16/18 0910 | I12: Tylenol | J12: 50 | K12: 6 | L12: 0 | M12: 1 | P12: =ISODD(A12) -> FALSE
A13: =IF(ROW()=2,1,IF(B13=B12,A12,A12+1)) -> 4 | B13: JC004 | C13: 6/16/18 0835 | D13: 6/17/18 0702 | E13: 40 | F13: Black | G13: SVD | H13: 06/16/18 1236 | I13: Ibuprofen | J13: 800 | K13: 7 | L13: 0 | M13: 3 | P13: =ISODD(A13) -> FALSE
A14: =IF(ROW()=2,1,IF(B14=B13,A13,A13+1)) -> 4 | B14: JC004 | C14: 6/16/18 0835 | D14: 6/17/18 0702 | E14: 40 | F14: Black | G14: SVD | H14: 6/16/18 1236 | I14: Percocet | J14: 1 tab | K14: 7 | L14: 0 | M14: 3 | P14: =ISODD(A14) -> FALSE
A15: =IF(ROW()=2,1,IF(B15=B14,A14,A14+1)) -> 4 | B15: JC004 | C15: 6/16/18 0835 | D15: 6/17/18 0702 | E15: 40 | F15: Black | G15: SVD | H15: 6/16/18 2211 | I15: Ibuprofen | J15: 800 | K15: 2 | L15: 0 | M15: 3 | P15: =ISODD(A15) -> FALSE
A16: =IF(ROW()=2,1,IF(B16=B15,A15,A15+1)) -> 4 | B16: JC004 | C16: 6/16/18 0835 | D16: 6/17/18 0702 | E16: 40 | F16: Black | G16: SVD | H16: 6/16/18 2211 | I16: Percocet | J16: 1 tab | K16: 2 | L16: 0 | M16: 3 | P16: =ISODD(A16) -> FALSE
A17: =IF(ROW()=2,1,IF(B17=B16,A16,A16+1)) -> 4 | B17: JC004 | C17: 6/16/18 0835 | D17: 6/17/18 0702 | E17: 40 | F17: Black | G17: SVD | H17: 6/17/18 0702 | I17: Ibuprofen | J17: 800 | K17: 3 | L17: 0 | M17: 3 | P17: =ISODD(A17) -> FALSE
A18: =IF(ROW()=2,1,IF(B18=B17,A17,A17+1)) -> 4 | B18: JC004 | C18: 6/16/18 0835 | D18: 6/17/18 0702 | E18: 40 | F18: Black | G18: SVD | H18: 6/17/18 0702 | I18: Percocet | J18: 1 tab | K18: 3 | L18: 0 | M18: 3 | P18: =ISODD(A18) -> FALSE
A19: =IF(ROW()=2,1,IF(B19=B18,A18,A18+1)) -> 5 | B19: G5005 | C19: 6/15/18 1030 | D19: 6/16/18 0805 | E19: 29 | F19: Black | G19: Caesarean | H19: 6/15/18 1521 | I19: Toradol | J19: 30 | K19: 2 | L19: 0 | M19: 3 | P19: =ISODD(A19) -> TRUE
A20: =IF(ROW()=2,1,IF(B20=B19,A19,A19+1)) -> 5 | B20: G5005 | C20: 6/15/18 1030 | D20: 6/16/18 0805 | E20: 29 | F20: Black | G20: Caesarean | H20: 6/15/18 2051 | I20: Toradol | J20: 30 | K20: 5 | L20: 3 | M20: 3 | P20: =ISODD(A20) -> TRUE
A21: =IF(ROW()=2,1,IF(B21=B20,A20,A20+1)) -> 5 | B21: G5005 | C21: 6/15/18 1030 | D21: 6/16/18 0805 | E21: 29 | F21: Black | G21: Caesarean | H21: 6/16/18 0132 | I21: Percocet | J21: 1 tab | K21: 6 | L21: 5 | M21: 3 | P21: =ISODD(A21) -> TRUE
A22: =IF(ROW()=2,1,IF(B22=B21,A21,A21+1)) -> 5 | B22: G5005 | C22: 6/15/18 1030 | D22: 6/16/18 0805 | E22: 29 | F22: Black | G22: Caesarean | H22: 6/16/18 0455 | I22: Toradol | J22: 30 | K22: 6 | L22: 0 | M22: 3 | P22: =ISODD(A22) -> TRUE
A23: =IF(ROW()=2,1,IF(B23=B22,A22,A22+1)) -> 5 | B23: G5005 | C23: 6/15/18 1030 | D23: 6/16/18 0805 | E23: 29 | F23: Black | G23: Caesarean | H23: 6/16/18 0805 | I23: Percocet | J23: 2 tabs | K23: 6 | L23: 0 | M23: 3 | P23: =ISODD(A23) -> TRUE
A24: =IF(ROW()=2,1,IF(B24=B23,A23,A23+1)) -> 6 | B24: KK006 | C24: 6/16/18 0315 | D24: 6/17/18 0313 | E24: 39 | F24: White | G24: SVD | H24: 6/16/18 1011 | I24: Ibuprofen | J24: 800 | K24: 4 | L24: 2 | M24: 3 | P24: =ISODD(A24) -> FALSE
A25: =IF(ROW()=2,1,IF(B25=B24,A24,A24+1)) -> 6 | B25: KK006 | C25: 6/16/18 0315 | D25: 6/17/18 0313 | E25: 39 | F25: White | G25: SVD | H25: 6/16/18 2021 | I25: Ibuprofen | J25: 800 | K25: 4 | L25: No F/u | M25: 3 | P25: =ISODD(A25) -> FALSE
A26: =IF(ROW()=2,1,IF(B26=B25,A25,A25+1)) -> 6 | B26: KK006 | C26: 6/16/18 0315 | D26: 6/17/18 0313 | E26: 39 | F26: White | G26: SVD | H26: 6/17/18 0313 | I26: Ibuprofen | J26: 800 | K26: 4 | L26: No F/u | M26: 3 | P26: =ISODD(A26) -> FALSE
A27: =IF(ROW()=2,1,IF(B27=B26,A26,A26+1)) -> 7 | B27: JM007 | C27: 6/16/18 0802 | D27: 6/17/18 0555 | E27: 40 | F27: White | G27: SVD | H27: 6/16/18 0827 | I27: Ibuprofen | J27: 800 | K27: 5 | L27: 4 | M27: 1 or 2 | P27: =ISODD(A27) -> TRUE
A28: =IF(ROW()=2,1,IF(B28=B27,A27,A27+1)) -> 7 | B28: JM007 | C28: 6/16/18 0802 | D28: 6/17/18 0555 | E28: 40 | F28: White | G28: SVD | H28: 06/16/18 1433 | I28: Ibuprofen | J28: 800 | K28: 0 | L28: No F/u | M28: 1 or 2 | P28: =ISODD(A28) -> TRUE
A29: =IF(ROW()=2,1,IF(B29=B28,A28,A28+1)) -> 7 | B29: JM007 | C29: 6/16/18 0802 | D29: 6/17/18 0555 | E29: 40 | F29: White | G29: SVD | H29: 6/16/18 2003 | I29: Tylenol | J29: 650 | K29: 2 | L29: No F/u | M29: 2 | P29: =ISODD(A29) -> TRUE
A30: =IF(ROW()=2,1,IF(B30=B29,A29,A29+1)) -> 7 | B30: JM007 | C30: 6/16/18 0802 | D30: 6/17/18 0555 | E30: 40 | F30: White | G30: SVD | H30: 6/17/18 0555 | I30: Tylenol | J30: 650 | K30: 0 | L30: No F/u | M30: 2 | P30: =ISODD(A30) -> TRUE
A31: =IF(ROW()=2,1,IF(B31=B30,A30,A30+1)) -> 8 | B31: 2D008 | C31: 6/15/18 1936 | D31: 6/16/18 1724 | E31: 36 | F31: Black | G31: Caesarean | H31: 6/16/18 0750 | I31: Toradol | J31: 30 | K31: 9 | L31: 9 | M31: 2 | P31: =ISODD(A31) -> FALSE
A32: =IF(ROW()=2,1,IF(B32=B31,A31,A31+1)) -> 8 | B32: 2D008 | C32: 6/15/18 1936 | D32: 6/16/18 1724 | E32: 36 | F32: Black | G32: Caesarean | H32: 6/16/18 0804 | I32: Percocet | J32: 1 | K32: 9 | L32: 3 | M32: 4 | P32: =ISODD(A32) -> FALSE
A33: =IF(ROW()=2,1,IF(B33=B32,A32,A32+1)) -> 8 | B33: 2D008 | C33: 6/15/18 1936 | D33: 6/16/18 1724 | E33: 36 | F33: Black | G33: Caesarean | H33: 6/16/18 1245 | I33: Percocet | J33: 1 | K33: 8 | L33: 4 | M33: 4 | P33: =ISODD(A33) -> FALSE
A34: =IF(ROW()=2,1,IF(B34=B33,A33,A33+1)) -> 8 | B34: 2D008 | C34: 6/15/18 1936 | D34: 6/16/18 1724 | E34: 36 | F34: Black | G34: Caesarean | H34: 6/16/18 1414 | I34: Toradol | J34: 30 | K34: 5 | L34: 4 | M34: 2 | P34: =ISODD(A34) -> FALSE
A35: =IF(ROW()=2,1,IF(B35=B34,A34,A34+1)) -> 8 | B35: 2D008 | C35: 6/15/18 1936 | D35: 6/16/18 1724 | E35: 36 | F35: Black | G35: Caesarean | H35: 6/16/18 1724 | I35: Percocet | J35: 2 | K35: 3 | L35: 1 | M35: 4 | N35: x | P35: =ISODD(A35) -> FALSE
A36: =IF(ROW()=2,1,IF(B36=B35,A35,A35+1)) -> 9 | B36: MR009 | C36: 06/16/18 1445 | D36: 6/17/18 1336 | E36: 21 | F36: Black | G36: Caesarean | H36: 6/16/18 1235 | I36: Toradol | J36: 30 | K36: 5 | L36: 0 | P36: =ISODD(A36) -> TRUE
A37: =IF(ROW()=2,1,IF(B37=B36,A36,A36+1)) -> 9 | B37: MR009 | C37: 06/16/18 1445 | D37: 6/17/18 1336 | E37: 21 | F37: Black | G37: Caesarean | H37: 6/17/18 0035 | I37: Toradol | J37: 30 | K37: 7 | L37: 3 | P37: =ISODD(A37) -> TRUE
A38: =IF(ROW()=2,1,IF(B38=B37,A37,A37+1)) -> 9 | B38: MR009 | C38: 06/16/18 1445 | D38: 6/17/18 1336 | E38: 21 | F38: Black | G38: Caesarean | H38: 6/17/18 0726 | I38: Toradol | J38: 30 | K38: 7 | L38: No F/u | P38: =ISODD(A38) -> TRUE
A39: =IF(ROW()=2,1,IF(B39=B38,A38,A38+1)) -> 9 | B39: MR009 | C39: 06/16/18 1445 | D39: 6/17/18 1336 | E39: 21 | F39: Black | G39: Caesarean | H39: 6/17/18 1058 | I39: Percocet | J39: 1 | K39: 5 | L39: No F/u | P39: =ISODD(A39) -> TRUE
A40: =IF(ROW()=2,1,IF(B40=B39,A39,A39+1)) -> 9 | B40: MR009 | C40: 06/16/18 1445 | D40: 6/17/18 1336 | E40: 21 | F40: Black | G40: Caesarean | H40: 6/17/18 1336 | I40: Toradol | J40: 30 | K40: 5 | L40: 0 | P40: =ISODD(A40) -> TRUE
...

Sheet Data
A1: Record Number | B1: Patient ID | C1: Start Time and Date | D1: End Date and Time | E1: Age | F1: Race | G1: Type of Delivery | H1: Date and Time | I1: Pain Medication | J1: Dose | K1: Pain Intensity Rating (Before Medication) | L1: Pain Intensity Rating (After Medication) | M1: Frequency of Pain Medication Used | N1: Question | O1: Comment | P1: Color
A2: =IF(ISBLANK('Data Input'!A2),"",'Data Input'!A2) -> 1 | B2: =IF(ISBLANK('Data Input'!B2),"",'Data Input'!B2) -> CH001 | C2: =IF(ISBLANK('Data Input'!C2),"",'Data Input'!C2) -> 43266.826 | D2: =IF(ISBLANK('Data Input'!D2),"",'Data Input'!D2) -> 6/16/2018 1849 | E2: =IF(ISBLANK('Data Input'!E2),"",'Data Input'!E2) -> 29 | F2: =IF(ISBLANK('Data Input'!F2),"",'Data Input'!F2) -> White | G2: =IF(ISBLANK('Data Input'!G2),"",'Data Input'!G2) -> SVD | H2: =IF(ISBLANK('Data Input'!H2),"",'Data Input'!H2) -> 6/15/18 2216 | ... P2: =IF(ISBLANK('Data Input'!P2),"",'Data Input'!P2) -> TRUE
A3: =IF(ISBLANK('Data Input'!A3),"",'Data Input'!A3) -> 1 | B3: =IF(ISBLANK('Data Input'!B3),"",'Data Input'!B3) -> CH001 | C3: =IF(ISBLANK('Data Input'!C3),"",'Data Input'!C3) -> 43266.826 | D3: =IF(ISBLANK('Data Input'!D3),"",'Data Input'!D3) -> 6/16/2018 1849 | E3: =IF(ISBLANK('Data Input'!E3),"",'Data Input'!E3) -> 29 | F3: =IF(ISBLANK('Data Input'!F3),"",'Data Input'!F3) -> White | G3: =IF(ISBLANK('Data Input'!G3),"",'Data Input'!G3) -> SVD | H3: =IF(ISBLANK('Data Input'!H3),"",'Data Input'!H3) -> 6/16/18 0510 | ... P3: =IF(ISBLANK('Data Input'!P3),"",'Data Input'!P3) -> TRUE
A4: =IF(ISBLANK('Data Input'!A4),"",'Data Input'!A4) -> 1 | B4: =IF(ISBLANK('Data Input'!B4),"",'Data Input'!B4) -> CH001 | C4: =IF(ISBLANK('Data Input'!C4),"",'Data Input'!C4) -> 43266.826 | D4: =IF(ISBLANK('Data Input'!D4),"",'Data Input'!D4) -> 6/16/2018 1849 | E4: =IF(ISBLANK('Data Input'!E4),"",'Data Input'!E4) -> 29 | F4: =IF(ISBLANK('Data Input'!F4),"",'Data Input'!F4) -> White | G4: =IF(ISBLANK('Data Input'!G4),"",'Data Input'!G4) -> SVD | H4: =IF(ISBLANK('Data Input'!H4),"",'Data Input'!H4) -> 6/16/2018 1025 | ... P4: =IF(ISBLANK('Data Input'!P4),"",'Data Input'!P4) -> TRUE
A5: =IF(ISBLANK('Data Input'!A5),"",'Data Input'!A5) -> 1 | B5: =IF(ISBLANK('Data Input'!B5),"",'Data Input'!B5) -> CH001 | C5: =IF(ISBLANK('Data Input'!C5),"",'Data Input'!C5) -> 43266.826 | D5: =IF(ISBLANK('Data Input'!D5),"",'Data Input'!D5) -> 6/16/2018 1849 | E5: =IF(ISBLANK('Data Input'!E5),"",'Data Input'!E5) -> 29 | F5: =IF(ISBLANK('Data Input'!F5),"",'Data Input'!F5) -> White | G5: =IF(ISBLANK('Data Input'!G5),"",'Data Input'!G5) -> SVD | H5: =IF(ISBLANK('Data Input'!H5),"",'Data Input'!H5) -> 6/16/18 1849 | ... P5: =IF(ISBLANK('Data Input'!P5),"",'Data Input'!P5) -> TRUE
A6: =IF(ISBLANK('Data Input'!A6),"",'Data Input'!A6) -> 2 | B6: =IF(ISBLANK('Data Input'!B6),"",'Data Input'!B6) -> KV002 | C6: =IF(ISBLANK('Data Input'!C6),"",'Data Input'!C6) -> 06/15/18 0100 | D6: =IF(ISBLANK('Data Input'!D6),"",'Data Input'!D6) -> 43267 | E6: =IF(ISBLANK('Data Input'!E6),"",'Data Input'!E6) -> 18 | F6: =IF(ISBLANK('Data Input'!F6),"",'Data Input'!F6) -> White | G6: =IF(ISBLANK('Data Input'!G6),"",'Data Input'!G6) -> SVD | H6: =IF(ISBLANK('Data Input'!H6),"",'Data Input'!H6) -> 6/15/18 0538 | ... P6: =IF(ISBLANK('Data Input'!P6),"",'Data Input'!P6) -> FALSE
A7: =IF(ISBLANK('Data Input'!A7),"",'Data Input'!A7) -> 2 | B7: =IF(ISBLANK('Data Input'!B7),"",'Data Input'!B7) -> KV002 | C7: =IF(ISBLANK('Data Input'!C7),"",'Data Input'!C7) -> 06/15/18 0100 | D7: =IF(ISBLANK('Data Input'!D7),"",'Data Input'!D7) -> 43267 | E7: =IF(ISBLANK('Data Input'!E7),"",'Data Input'!E7) -> 18 | F7: =IF(ISBLANK('Data Input'!F7),"",'Data Input'!F7) -> White | G7: =IF(ISBLANK('Data Input'!G7),"",'Data Input'!G7) -> SVD | H7: =IF(ISBLANK('Data Input'!H7),"",'Data Input'!H7) -> 6/15/18 1533 | ... P7: =IF(ISBLANK('Data Input'!P7),"",'Data Input'!P7) -> FALSE
A8: =IF(ISBLANK('Data Input'!A8),"",'Data Input'!A8) -> 2 | B8: =IF(ISBLANK('Data Input'!B8),"",'Data Input'!B8) -> KV002 | C8: =IF(ISBLANK('Data Input'!C8),"",'Data Input'!C8) -> 06/15/18 0100 | D8: =IF(ISBLANK('Data Input'!D8),"",'Data Input'!D8) -> 43267 | E8: =IF(ISBLANK('Data Input'!E8),"",'Data Input'!E8) -> 18 | F8: =IF(ISBLANK('Data Input'!F8),"",'Data Input'!F8) -> White | G8: =IF(ISBLANK('Data Input'!G8),"",'Data Input'!G8) -> SVD | H8: =IF(ISBLANK('Data Input'!H8),"",'Data Input'!H8) -> 6/16/18 0220 | ... P8: =IF(ISBLANK('Data Input'!P8),"",'Data Input'!P8) -> FALSE
A9: =IF(ISBLANK('Data Input'!A9),"",'Data Input'!A9) -> 3 | B9: =IF(ISBLANK('Data Input'!B9),"",'Data Input'!B9) -> AK003 | C9: =IF(ISBLANK('Data Input'!C9),"",'Data Input'!C9) -> 6/15/18 1500 | D9: =IF(ISBLANK('Data Input'!D9),"",'Data Input'!D9) -> 6/16/18 0942 | E9: =IF(ISBLANK('Data Input'!E9),"",'Data Input'!E9) -> 26 | F9: =IF(ISBLANK('Data Input'!F9),"",'Data Input'!F9) -> White | G9: =IF(ISBLANK('Data Input'!G9),"",'Data Input'!G9) -> Caesarean | H9: =IF(ISBLANK('Data Input'!H9),"",'Data Input'!H9) -> 6/15/18 1550 | ... P9: =IF(ISBLANK('Data Input'!P9),"",'Data Input'!P9) -> TRUE
A10: =IF(ISBLANK('Data Input'!A10),"",'Data Input'!A10) -> 3 | B10: =IF(ISBLANK('Data Input'!B10),"",'Data Input'!B10) -> AK003 | C10: =IF(ISBLANK('Data Input'!C10),"",'Data Input'!C10) -> 6/15/18 1500 | D10: =IF(ISBLANK('Data Input'!D10),"",'Data Input'!D10) -> 6/16/18 0942 | E10: =IF(ISBLANK('Data Input'!E10),"",'Data Input'!E10) -> 26 | F10: =IF(ISBLANK('Data Input'!F10),"",'Data Input'!F10) -> White | G10: =IF(ISBLANK('Data Input'!G10),"",'Data Input'!G10) -> Caesarean | H10: =IF(ISBLANK('Data Input'!H10),"",'Data Input'!H10) -> 6/16/18 0835 | ... P10: =IF(ISBLANK('Data Input'!P10),"",'Data Input'!P10) -> TRUE
A11: =IF(ISBLANK('Data Input'!A11),"",'Data Input'!A11) -> 3 | B11: =IF(ISBLANK('Data Input'!B11),"",'Data Input'!B11) -> AK003 | C11: =IF(ISBLANK('Data Input'!C11),"",'Data Input'!C11) -> 6/15/18 1500 | D11: =IF(ISBLANK('Data Input'!D11),"",'Data Input'!D11) -> 6/16/18 0942 | E11: =IF(ISBLANK('Data Input'!E11),"",'Data Input'!E11) -> 26 | F11: =IF(ISBLANK('Data Input'!F11),"",'Data Input'!F11) -> White | G11: =IF(ISBLANK('Data Input'!G11),"",'Data Input'!G11) -> Caesarean | H11: =IF(ISBLANK('Data Input'!H11),"",'Data Input'!H11) -> 6/16/18 0942 | ... P11: =IF(ISBLANK('Data Input'!P11),"",'Data Input'!P11) -> TRUE
A12: =IF(ISBLANK('Data Input'!A12),"",'Data Input'!A12) -> 4 | B12: =IF(ISBLANK('Data Input'!B12),"",'Data Input'!B12) -> JC004 | C12: =IF(ISBLANK('Data Input'!C12),"",'Data Input'!C12) -> 6/16/18 0835 | D12: =IF(ISBLANK('Data Input'!D12),"",'Data Input'!D12) -> 6/17/18 0702 | E12: =IF(ISBLANK('Data Input'!E12),"",'Data Input'!E12) -> 40 | F12: =IF(ISBLANK('Data Input'!F12),"",'Data Input'!F12) -> Black | G12: =IF(ISBLANK('Data Input'!G12),"",'Data Input'!G12) -> SVD | H12: =IF(ISBLANK('Data Input'!H12),"",'Data Input'!H12) -> 6/16/18 0910 | ... P12: =IF(ISBLANK('Data Input'!P12),"",'Data Input'!P12) -> FALSE
A13: =IF(ISBLANK('Data Input'!A13),"",'Data Input'!A13) -> 4 | B13: =IF(ISBLANK('Data Input'!B13),"",'Data Input'!B13) -> JC004 | C13: =IF(ISBLANK('Data Input'!C13),"",'Data Input'!C13) -> 6/16/18 0835 | D13: =IF(ISBLANK('Data Input'!D13),"",'Data Input'!D13) -> 6/17/18 0702 | E13: =IF(ISBLANK('Data Input'!E13),"",'Data Input'!E13) -> 40 | F13: =IF(ISBLANK('Data Input'!F13),"",'Data Input'!F13) -> Black | G13: =IF(ISBLANK('Data Input'!G13),"",'Data Input'!G13) -> SVD | H13: =IF(ISBLANK('Data Input'!H13),"",'Data Input'!H13) -> 06/16/18 1236 | ... P13: =IF(ISBLANK('Data Input'!P13),"",'Data Input'!P13) -> FALSE
... A530: =IF(ISBLANK('Data Input'!A530),"",'Data Input'!A530) -> 74 | B530: =IF(ISBLANK('Data Input'!B530),"",'Data Input'!B530) | C530: =IF(ISBLANK('Data Input'!C530),"",'Data Input'!C530) | D530: =IF(ISBLANK('Data Input'!D530),"",'Data Input'!D530) | E530: =IF(ISBLANK('Data Input'!E530),"",'Data Input'!E530) | F530: =IF(ISBLANK('Data Input'!F530),"",'Data Input'!F530) | G530: =IF(ISBLANK('Data Input'!G530),"",'Data Input'!G530) | H530: =IF(ISBLANK('Data Input'!H530),"",'Data Input'!H530) | ... P530: =IF(ISBLANK('Data Input'!P530),"",'Data Input'!P530) -> FALSE

Sheet Legend
A1: Dose | F1: Patient ID
A2: 1 tab | B2: 5 mg oxycodone, 325 mg tylenol | F2: CH001
F3: KV002
A4: Shortcut | B4: Name | C4: Dose | D4: Frequency | F4: AK003
A5: bb | B5: Ibuprofen | C5: 800 | D5: 3 | F5: JC004
A6: rr | B6: Perocet | C6: 1 tab | D6: 3 | F6: G5005
A7: tt | B7: Tylenol | C7: 50 | D7: 1 | F7: KK006
A8: tr | B8: Toradel | C8: 30 | D8: 3 | F8: JM007
F9: 2D008
A10: Notes | F10: MR009
A11: "F/u" | B11: Follow up | F11: RL010
F12: RB011
F13: JL012
F14: BC013
F15: AV014
F16: LZ015
F17: JB016
F18: AE017
F19: SR018
F20: JM019
F21: CW020
F22: RE021
F23: MF022
... F59: YT 058
